Workbook
Name ImageRange: Assets!$F$3:$F$7
Name Img_Link: INDIRECT(Pivots!$N$67)
Name Slicer_Representative: #N/A

Sheet Pivots
A3: Call Count | B3: Total Amount | C3: Total Duration | D3: AVG Rating | E3: 5* Rating
A4: 1000 | B4: 96623 | C4: 89850 | D4: 3.8854 | E4: 307
A11: Call Count | B11: Total Amount | C11: Total Duration | D11: AVG Rating | E11: 5* Rating
A12: 186 | B12: 16651 | C12: 17807 | D12: 3.8973118 | E12: 62
A19: Row Labels | B19: Call Count | C19: Call Count2 | G19: Row Labels | H19: Call Count
A20: Jan | B20: 10 | C20: 10 | G20: Sunday | H20: 25
A21: Feb | B21: 11 | C21: 11 | G21: Monday | H21: 23
A22: Mar | B22: 30 | C22: 30 | G22: Tuesday | H22: 28
A23: Apr | B23: 23 | C23: 23 | G23: Wednesday | H23: 29
A24: May | B24: 22 | C24: 22 | G24: Thursday | H24: 18
A25: Jun | B25: 11 | C25: 11 | G25: Friday | H25: 29
A26: Jul | B26: 17 | C26: 17 | G26: Saturday | H26: 34
A27: Aug | B27: 12 | C27: 12 | G27: Grand Total | H27: 186
A28: Sep | B28: 13 | C28: 13
A29: Oct | B29: 15 | C29: 15
A30: Nov | B30: 8 | C30: 8
A31: Dec | B31: 14 | C31: 14
A32: Grand Total | B32: 186 | C32: 186
H35: for Graph | J35: Selected Rep | K35: =A50 -> R04
G37: Repps | H37: calls | I37: amount | J37: Sel.call | K37: Sel.Amount
A38: Row Labels | B38: Call Count | C38: Total Amount | G38: =A39 -> R01 | H38: =B39 -> 189 | I38: =C39 -> 18415 | J38: =IF(G38=K35,H38,NA()) -> #N/A | K38: =IF(G38=$K$35,I38,NA()) -> #N/A
A39: R01 | B39: 189 | C39: 18415 | G39: =A40 -> R02 | H39: =B40 -> 218 | I39: =C40 -> 20581 | J39: =IF(G39=$K$35,H39,NA()) -> #N/A | K39: =IF(G39=$K$35,I39,NA()) -> #N/A
A40: R02 | B40: 218 | C40: 20581 | G40: =A41 -> R03 | H40: =B41 -> 207 | I40: =C41 -> 20872 | J40: =IF(G40=$K$35,H40,NA()) -> #N/A | K40: =IF(G40=$K$35,I40,NA()) -> #N/A
A41: R03 | B41: 207 | C41: 20872 | G41: =A42 -> R04 | H41: =B42 -> 186 | I41: =C42 -> 16651 | J41: =IF(G41=$K$35,H41,NA()) -> 186 | K41: =IF(G41=$K$35,I41,NA()) -> 16651
A42: R04 | B42: 186 | C42: 16651 | G42: =A43 -> R05 | H42: =B43 -> 200 | I42: =C43 -> 20104 | J42: =IF(G42=$K$35,H42,NA()) -> #N/A | K42: =IF(G42=$K$35,I42,NA()) -> #N/A
A43: R05 | B43: 200 | C43: 20104
A44: Grand Total | B44: 1000 | C44: 96623
O48: INDEX(B:B, MATCH(A2, A:A, 0))
A49: Row Labels | E49: Call Count | F49: Column Labels
A50: R04 | E50: Row Labels | F50: Female | G50: Male | H50: Grand Total
E51: Cincinnati | F51: 144 | G51: 132 | H51: 276
E52: Cleveland | F52: 326 | G52: 63 | H52: 389
E53: Columbus | F53: 129 | G53: 206 | H53: 335 | M53: REP Summary | N53: =A12/A4 -> 0.186
E54: Grand Total | F54: 599 | G54: 401 | H54: 1000 | M54: calls | N54: =INDEX(H38:H42, MATCH(A50,G38:G42,0)) -> 186
M55: amount | N55: =INDEX(I38:I42, MATCH(A50,G38:G42,0)) -> 16651
A57: Row Labels | B57: Call Count | M57: call rank | N57: =_xlfn.RANK.AVG(N54,H38:H42) -> 5
A58: 1 | B58: 3 | E58: Total Amount | F58: Column Labels | M58: amount rank | N58: =_xlfn.RANK.AVG(N55,I38:I42) -> 5
A59: 2 | B59: 10 | E59: Row Labels | F59: R01 | G59: R02 | H59: R03 | I59: R04 | J59: R05 | K59: Grand Total
A60: 3 | B60: 41 | E60: Cincinnati | M60: Labels:
A61: 4 | B61: 70 | E61: C0003 | F61: 891 | G61: 1332 | H61: 1282 | I61: 739 | J61: 560 | K61: 4804 | N61: ="% of calls: "&TEXT(N53,"0%") -> % of calls: 19%
...

Sheet Data
B1: Call Centre Data
B3: Call number | C3: Customer ID | D3: Duration | E3: Representative | F3: Date of Call | G3: Purchase Amount | H3: Satisfaction Rating | I3: FY | J3: Day of week | K3: Duration Bucket | L3: Rating rounded | Q3: Customer ID | R3: Gedner | S3: Age | T3: City
B4: Call_7271 | C4: C0003 | D4: 116 | E4: R05 | F4: 44927 | G4: 128 | H4: 4.9 | I4: =IF(MONTH(calls[[#This Row],[Date of Call]])<=6, YEAR(calls[[#This Row],[Date of Call]]), YEAR(calls[[#This Row],[Date of Call]])+1) -> 2023 | J4: =TEXT(calls[[#This Row],[Date of Call]],"DDDD") -> Sunday | K4: {=_xlfn.IFS(calls[[#This Row],[Duration]]<=10,"Under 10 mins", calls[[#This Row],[Duration]]<=30, "10 to 30 mins", calls[[#This Row],[Duration]]<=60, "30 to 60 mins", calls[[#This Row],[Duration]]<=120, "1 to 2 hours", TRUE, "More than 2 hours")} -> 1 to 2 hours | L4: =ROUND(calls[[#This Row],[Satisfaction Rating]],0) -> 5 | Q4: C0001 | R4: Male | S4: 41 | T4: Columbus
B5: Call_7272 | C5: C0004 | D5: 119 | E5: R05 | F5: 44927 | G5: 135 | H5: 2.9 | I5: =IF(MONTH(calls[[#This Row],[Date of Call]])<=6, YEAR(calls[[#This Row],[Date of Call]]), YEAR(calls[[#This Row],[Date of Call]])+1) -> 2023 | J5: =TEXT(calls[[#This Row],[Date of Call]],"DDDD") -> Sunday | K5: {=_xlfn.IFS(calls[[#This Row],[Duration]]<=10,"Under 10 mins", calls[[#This Row],[Duration]]<=30, "10 to 30 mins", calls[[#This Row],[Duration]]<=60, "30 to 60 mins", calls[[#This Row],[Duration]]<=120, "1 to 2 hours", TRUE, "More than 2 hours")} -> 1 to 2 hours | L5: =ROUND(calls[[#This Row],[Satisfaction Rating]],0) -> 3 | Q5: C0002 | R5: Male | S5: 31 | T5: Cleveland
B6: Call_7273 | C6: C0005 | D6: 68 | E6: R02 | F6: 44927 | G6: 66 | H6: 4.7 | I6: =IF(MONTH(calls[[#This Row],[Date of Call]])<=6, YEAR(calls[[#This Row],[Date of Call]]), YEAR(calls[[#This Row],[Date of Call]])+1) -> 2023 | J6: =TEXT(calls[[#This Row],[Date of Call]],"DDDD") -> Sunday | K6: {=_xlfn.IFS(calls[[#This Row],[Duration]]<=10,"Under 10 mins", calls[[#This Row],[Duration]]<=30, "10 to 30 mins", calls[[#This Row],[Duration]]<=60, "30 to 60 mins", calls[[#This Row],[Duration]]<=120, "1 to 2 hours", TRUE, "More than 2 hours")} -> 1 to 2 hours | L6: =ROUND(calls[[#This Row],[Satisfaction Rating]],0) -> 5 | Q6: C0003 | R6: Male | S6: 26 | T6: Cincinnati
B7: Call_7274 | C7: C0014 | D7: 119 | E7: R02 | F7: 44927 | G7: 22 | H7: 2.9 | I7: =IF(MONTH(calls[[#This Row],[Date of Call]])<=6, YEAR(calls[[#This Row],[Date of Call]]), YEAR(calls[[#This Row],[Date of Call]])+1) -> 2023 | J7: =TEXT(calls[[#This Row],[Date of Call]],"DDDD") -> Sunday | K7: {=_xlfn.IFS(calls[[#This Row],[Duration]]<=10,"Under 10 mins", calls[[#This Row],[Duration]]<=30, "10 to 30 mins", calls[[#This Row],[Duration]]<=60, "30 to 60 mins", calls[[#This Row],[Duration]]<=120, "1 to 2 hours", TRUE, "More than 2 hours")} -> 1 to 2 hours | L7: =ROUND(calls[[#This Row],[Satisfaction Rating]],0) -> 3 | Q7: C0004 | R7: Male | S7: 36 | T7: Cincinnati
B8: Call_7275 | C8: C0011 | D8: 128 | E8: R01 | F8: 44928 | G8: 31 | H8: 2.8 | I8: =IF(MONTH(calls[[#This Row],[Date of Call]])<=6, YEAR(calls[[#This Row],[Date of Call]]), YEAR(calls[[#This Row],[Date of Call]])+1) -> 2023 | J8: =TEXT(calls[[#This Row],[Date of Call]],"DDDD") -> Monday | K8: {=_xlfn.IFS(calls[[#This Row],[Duration]]<=10,"Under 10 mins", calls[[#This Row],[Duration]]<=30, "10 to 30 mins", calls[[#This Row],[Duration]]<=60, "30 to 60 mins", calls[[#This Row],[Duration]]<=120, "1 to 2 hours", TRUE, "More than 2 hours")} -> More than 2 hours | L8: =ROUND(calls[[#This Row],[Satisfaction Rating]],0) -> 3 | Q8: C0005 | R8: Male | S8: 37 | T8: Columbus
B9: Call_7276 | C9: C0011 | D9: 49 | E9: R02 | F9: 44929 | G9: 135 | H9: 4.8 | I9: =IF(MONTH(calls[[#This Row],[Date of Call]])<=6, YEAR(calls[[#This Row],[Date of Call]]), YEAR(calls[[#This Row],[Date of Call]])+1) -> 2023 | J9: =TEXT(calls[[#This Row],[Date of Call]],"DDDD") -> Tuesday | K9: {=_xlfn.IFS(calls[[#This Row],[Duration]]<=10,"Under 10 mins", calls[[#This Row],[Duration]]<=30, "10 to 30 mins", calls[[#This Row],[Duration]]<=60, "30 to 60 mins", calls[[#This Row],[Duration]]<=120, "1 to 2 hours", TRUE, "More than 2 hours")} -> 30 to 60 mins | L9: =ROUND(calls[[#This Row],[Satisfaction Rating]],0) -> 5 | Q9: C0006 | R9: Male | S9: 23 | T9: Columbus
B10: Call_7277 | C10: C0007 | D10: 84 | E10: R05 | F10: 44929 | G10: 60 | H10: 4.7 | I10: =IF(MONTH(calls[[#This Row],[Date of Call]])<=6, YEAR(calls[[#This Row],[Date of Call]]), YEAR(calls[[#This Row],[Date of Call]])+1) -> 2023 | J10: =TEXT(calls[[#This Row],[Date of Call]],"DDDD") -> Tuesday | K10: {=_xlfn.IFS(calls[[#This Row],[Duration]]<=10,"Under 10 mins", calls[[#This Row],[Duration]]<=30, "10 to 30 mins", calls[[#This Row],[Duration]]<=60, "30 to 60 mins", calls[[#This Row],[Duration]]<=120, "1 to 2 hours", TRUE, "More than 2 hours")} -> 1 to 2 hours | L10: =ROUND(calls[[#This Row],[Satisfaction Rating]],0) -> 5 | Q10: C0007 | R10: Female | S10: 22 | T10: Cleveland
B11: Call_7278 | C11: C0003 | D11: 103 | E11: R04 | F11: 44929 | G11: 148 | H11: 4.4 | I11: =IF(MONTH(calls[[#This Row],[Date of Call]])<=6, YEAR(calls[[#This Row],[Date of Call]]), YEAR(calls[[#This Row],[Date of Call]])+1) -> 2023 | J11: =TEXT(calls[[#This Row],[Date of Call]],"DDDD") -> Tuesday | K11: {=_xlfn.IFS(calls[[#This Row],[Duration]]<=10,"Under 10 mins", calls[[#This Row],[Duration]]<=30, "10 to 30 mins", calls[[#This Row],[Duration]]<=60, "30 to 60 mins", calls[[#This Row],[Duration]]<=120, "1 to 2 hours", TRUE, "More than 2 hours")} -> 1 to 2 hours | L11: =ROUND(calls[[#This Row],[Satisfaction Rating]],0) -> 4 | Q11: C0008 | R11: Female | S11: 42 | T11: Cleveland
B12: Call_7279 | C12: C0005 | D12: 31 | E12: R02 | F12: 44929 | G12: 135 | H12: 3.6 | I12: =IF(MONTH(calls[[#This Row],[Date of Call]])<=6, YEAR(calls[[#This Row],[Date of Call]]), YEAR(calls[[#This Row],[Date of Call]])+1) -> 2023 | J12: =TEXT(calls[[#This Row],[Date of Call]],"DDDD") -> Tuesday | K12: {=_xlfn.IFS(calls[[#This Row],[Duration]]<=10,"Under 10 mins", calls[[#This Row],[Duration]]<=30, "10 to 30 mins", calls[[#This Row],[Duration]]<=60, "30 to 60 mins", calls[[#This Row],[Duration]]<=120, "1 to 2 hours", TRUE, "More than 2 hours")} -> 30 to 60 mins | L12: =ROUND(calls[[#This Row],[Satisfaction Rating]],0) -> 4 | Q12: C0009 | R12: Female | S12: 25 | T12: Columbus
B13: Call_7280 | C13: C0010 | D13: 44 | E13: R03 | F13: 44929 | G13: 105 | H13: 2.9 | I13: =IF(MONTH(calls[[#This Row],[Date of Call]])<=6, YEAR(calls[[#This Row],[Date of Call]]), YEAR(calls[[#This Row],[Date of Call]])+1) -> 2023 | J13: =TEXT(calls[[#This Row],[Date of Call]],"DDDD") -> Tuesday | K13: {=_xlfn.IFS(calls[[#This Row],[Duration]]<=10,"Under 10 mins", calls[[#This Row],[Duration]]<=30, "10 to 30 mins", calls[[#This Row],[Duration]]<=60, "30 to 60 mins", calls[[#This Row],[Duration]]<=120, "1 to 2 hours", TRUE, "More than 2 hours")} -> 30 to 60 mins | L13: =ROUND(calls[[#This Row],[Satisfaction Rating]],0) -> 3 | Q13: C0010 | R13: Female | S13: 30 | T13: Cleveland
B14: Call_7281 | C14: C0011 | D14: 102 | E14: R02 | F14: 44929 | G14: 69 | H14: 4.9 | I14: =IF(MONTH(calls[[#This Row],[Date of Call]])<=6, YEAR(calls[[#This Row],[Date of Call]]), YEAR(calls[[#This Row],[Date of Call]])+1) -> 2023 | J14: =TEXT(calls[[#This Row],[Date of Call]],"DDDD") -> Tuesday | K14: {=_xlfn.IFS(calls[[#This Row],[Duration]]<=10,"Under 10 mins", calls[[#This Row],[Duration]]<=30, "10 to 30 mins", calls[[#This Row],[Duration]]<=60, "30 to 60 mins", calls[[#This Row],[Duration]]<=120, "1 to 2 hours", TRUE, "More than 2 hours")} -> 1 to 2 hours | L14: =ROUND(calls[[#This Row],[Satisfaction Rating]],0) -> 5 | Q14: C0011 | R14: Female | S14: 30 | T14: Cincinnati
B15: Call_7282 | C15: C0013 | D15: 135 | E15: R05 | F15: 44929 | G15: 46 | H15: 3.4 | I15: =IF(MONTH(calls[[#This Row],[Date of Call]])<=6, YEAR(calls[[#This Row],[Date of Call]]), YEAR(calls[[#This Row],[Date of Call]])+1) -> 2023 | J15: =TEXT(calls[[#This Row],[Date of Call]],"DDDD") -> Tuesday | K15: {=_xlfn.IFS(calls[[#This Row],[Duration]]<=10,"Under 10 mins", calls[[#This Row],[Duration]]<=30, "10 to 30 mins", calls[[#This Row],[Duration]]<=60, "30 to 60 mins", calls[[#This Row],[Duration]]<=120, "1 to 2 hours", TRUE, "More than 2 hours")} -> More than 2 hours | L15: =ROUND(calls[[#This Row],[Satisfaction Rating]],0) -> 3 | Q15: C0012 | R15: Female | S15: 28 | T15: Cincinnati
... B18: Call_7285 | C18: C0013 | D18: 48 | E18: R01 | F18: 44930 | G18: 68 | H18: 4.9 | I18: =IF(MONTH(calls[[#This Row],[Date of Call]])<=6, YEAR(calls[[#This Row],[Date of Call]]), YEAR(calls[[#This Row],[Date of Call]])+1) -> 2023 | J18: =TEXT(calls[[#This Row],[Date of Call]],"DDDD") -> Wednesday | K18: {=_xlfn.IFS(calls[[#This Row],[Duration]]<=10,"Under 10 mins", calls[[#This Row],[Duration]]<=30, "10 to 30 mins", calls[[#This Row],[Duration]]<=60, "30 to 60 mins", calls[[#This Row],[Duration]]<=120, "1 to 2 hours", TRUE, "More than 2 hours")} -> 30 to 60 mins | L18: =ROUND(calls[[#This Row],[Satisfaction Rating]],0) -> 5 | Q18: C0015 | R18: Female | S18: 43 | T18: Cleveland
B19: Call_7286 | C19: C0010 | D19: 176 | E19: R05 | F19: 44931 | G19: 24 | H19: 4.8 | I19: =IF(MONTH(calls[[#This Row],[Date of Call]])<=6, YEAR(calls[[#This Row],[Date of Call]]), YEAR(calls[[#This Row],[Date of Call]])+1) -> 2023 | J19: =TEXT(calls[[#This Row],[Date of Call]],"DDDD") -> Thursday | K19: {=_xlfn.IFS(calls[[#This Row],[Duration]]<=10,"Under 10 mins", calls[[#This Row],[Duration]]<=30, "10 to 30 mins", calls[[#This Row],[Duration]]<=60, "30 to 60 mins", calls[[#This Row],[Duration]]<=120, "1 to 2 hours", TRUE, "More than 2 hours")} -> More than 2 hours | L19: =ROUND(calls[[#This Row],[Satisfaction Rating]],0) -> 5
B20: Call_7287 | C20: C0010 | D20: 99 | E20: R01 | F20: 44931 | G20: 195 | H20: 3.9 | I20: =IF(MONTH(calls[[#This Row],[Date of Call]])<=6, YEAR(calls[[#This Row],[Date of Call]]), YEAR(calls[[#This Row],[Date of Call]])+1) -> 2023 | J20: =TEXT(calls[[#This Row],[Date of Call]],"DDDD") -> Thursday | K20: {=_xlfn.IFS(calls[[#This Row],[Duration]]<=10,"Under 10 mins", calls[[#This Row],[Duration]]<=30, "10 to 30 mins", calls[[#This Row],[Duration]]<=60, "30 to 60 mins", calls[[#This Row],[Duration]]<=120, "1 to 2 hours", TRUE, "More than 2 hours")} -> 1 to 2 hours | L20: =ROUND(calls[[#This Row],[Satisfaction Rating]],0) -> 4
B21: Call_7288 | C21: C0009 | D21: 28 | E21: R03 | F21: 44931 | G21: 28 | H21: 3.8 | I21: =IF(MONTH(calls[[#This Row],[Date of Call]])<=6, YEAR(calls[[#This Row],[Date of Call]]), YEAR(calls[[#This Row],[Date of Call]])+1) -> 2023 | J21: =TEXT(calls[[#This Row],[Date of Call]],"DDDD") -> Thursday | K21: {=_xlfn.IFS(calls[[#This Row],[Duration]]<=10,"Under 10 mins", calls[[#This Row],[Duration]]<=30, "10 to 30 mins", calls[[#This Row],[Duration]]<=60, "30 to 60 mins", calls[[#This Row],[Duration]]<=120, "1 to 2 hours", TRUE, "More than 2 hours")} -> 10 to 30 mins | L21: =ROUND(calls[[#This Row],[Satisfaction Rating]],0) -> 4
B22: Call_7289 | C22: C0007 | D22: 54 | E22: R02 | F22: 44931 | G22: 170 | H22: 4.3 | I22: =IF(MONTH(calls[[#This Row],[Date of Call]])<=6, YEAR(calls[[#This Row],[Date of Call]]), YEAR(calls[[#This Row],[Date of Call]])+1) -> 2023 | J22: =TEXT(calls[[#This Row],[Date of Call]],"DDDD") -> Thursday | K22: {=_xlfn.IFS(calls[[#This Row],[Duration]]<=10,"Under 10 mins", calls[[#This Row],[Duration]]<=30, "10 to 30 mins", calls[[#This Row],[Duration]]<=60, "30 to 60 mins", calls[[#This Row],[Duration]]<=120, "1 to 2 hours", TRUE, "More than 2 hours")} -> 30 to 60 mins | L22: =ROUND(calls[[#This Row],[Satisfaction Rating]],0) -> 4
B23: Call_7290 | C23: C0006 | D23: 48 | E23: R05 | F23: 44932 | G23: 30 | H23: 4.4 | I23: =IF(MONTH(calls[[#This Row],[Date of Call]])<=6, YEAR(calls[[#This Row],[Date of Call]]), YEAR(calls[[#This Row],[Date of Call]])+1) -> 2023 | J23: =TEXT(calls[[#This Row],[Date of Call]],"DDDD") -> Friday | K23: {=_xlfn.IFS(calls[[#This Row],[Duration]]<=10,"Under 10 mins", calls[[#This Row],[Duration]]<=30, "10 to 30 mins", calls[[#This Row],[Duration]]<=60, "30 to 60 mins", calls[[#This Row],[Duration]]<=120, "1 to 2 hours", TRUE, "More than 2 hours")} -> 30 to 60 mins | L23: =ROUND(calls[[#This Row],[Satisfaction Rating]],0) -> 4
B24: Call_7291 | C24: C0004 | D24: 128 | E24: R05 | F24: 44932 | G24: 72 | H24: 5 | I24: =IF(MONTH(calls[[#This Row],[Date of Call]])<=6, YEAR(calls[[#This Row],[Date of Call]]), YEAR(calls[[#This Row],[Date of Call]])+1) -> 2023 | J24: =TEXT(calls[[#This Row],[Date of Call]],"DDDD") -> Friday | K24: {=_xlfn.IFS(calls[[#This Row],[Duration]]<=10,"Under 10 mins", calls[[#This Row],[Duration]]<=30, "10 to 30 mins", calls[[#This Row],[Duration]]<=60, "30 to 60 mins", calls[[#This Row],[Duration]]<=120, "1 to 2 hours", TRUE, "More than 2 hours")} -> More than 2 hours | L24: =ROUND(calls[[#This Row],[Satisfaction Rating]],0) -> 5
B25: Call_7292 | C25: C0004 | D25: 38 | E25: R04 | F25: 44933 | G25: 92 | H25: 4.9 | I25: =IF(MONTH(calls[[#This Row],[Date of Call]])<=6, YEAR(calls[[#This Row],[Date of Call]]), YEAR(calls[[#This Row],[Date of Call]])+1) -> 2023 | J25: =TEXT(calls[[#This Row],[Date of Call]],"DDDD") -> Saturday | K25: {=_xlfn.IFS(calls[[#This Row],[Duration]]<=10,"Under 10 mins", calls[[#This Row],[Duration]]<=30, "10 to 30 mins", calls[[#This Row],[Duration]]<=60, "30 to 60 mins", calls[[#This Row],[Duration]]<=120, "1 to 2 hours", TRUE, "More than 2 hours")} -> 30 to 60 mins | L25: =ROUND(calls[[#This Row],[Satisfaction Rating]],0) -> 5
B26: Call_7293 | C26: C0003 | D26: 67 | E26: R04 | F26: 44934 | G26: 165 | H26: 4.5 | I26: =IF(MONTH(calls[[#This Row],[Date of Call]])<=6, YEAR(calls[[#This Row],[Date of Call]]), YEAR(calls[[#This Row],[Date of Call]])+1) -> 2023 | J26: =TEXT(calls[[#This Row],[Date of Call]],"DDDD") -> Sunday | K26: {=_xlfn.IFS(calls[[#This Row],[Duration]]<=10,"Under 10 mins", calls[[#This Row],[Duration]]<=30, "10 to 30 mins", calls[[#This Row],[Duration]]<=60, "30 to 60 mins", calls[[#This Row],[Duration]]<=120, "1 to 2 hours", TRUE, "More than 2 hours")} -> 1 to 2 hours | L26: =ROUND(calls[[#This Row],[Satisfaction Rating]],0) -> 5
B27: Call_7294 | C27: C0015 | D27: 58 | E27: R02 | F27: 44934 | G27: 140 | H27: 2.1 | I27: =IF(MONTH(calls[[#This Row],[Date of Call]])<=6, YEAR(calls[[#This Row],[Date of Call]]), YEAR(calls[[#This Row],[Date of Call]])+1) -> 2023 | J27: =TEXT(calls[[#This Row],[Date of Call]],"DDDD") -> Sunday | K27: {=_xlfn.IFS(calls[[#This Row],[Duration]]<=10,"Under 10 mins", calls[[#This Row],[Duration]]<=30, "10 to 30 mins", calls[[#This Row],[Duration]]<=60, "30 to 60 mins", calls[[#This Row],[Duration]]<=120, "1 to 2 hours", TRUE, "More than 2 hours")} -> 30 to 60 mins | L27: =ROUND(calls[[#This Row],[Satisfaction Rating]],0) -> 2
B28: Call_7295 | C28: C0010 | D28: 54 | E28: R01 | F28: 44934 | G28: 111 | H28: 3.3 | I28: =IF(MONTH(calls[[#This Row],[Date of Call]])<=6, YEAR(calls[[#This Row],[Date of Call]]), YEAR(calls[[#This Row],[Date of Call]])+1) -> 2023 | J28: =TEXT(calls[[#This Row],[Date of Call]],"DDDD") -> Sunday | K28: {=_xlfn.IFS(calls[[#This Row],[Duration]]<=10,"Under 10 mins", calls[[#This Row],[Duration]]<=30, "10 to 30 mins", calls[[#This Row],[Duration]]<=60, "30 to 60 mins", calls[[#This Row],[Duration]]<=120, "1 to 2 hours", TRUE, "More than 2 hours")} -> 30 to 60 mins | L28: =ROUND(calls[[#This Row],[Satisfaction Rating]],0) -> 3
B29: Call_7296 | C29: C0012 | D29: 28 | E29: R05 | F29: 44935 | G29: 63 | H29: 4.1 | I29: =IF(MONTH(calls[[#This Row],[Date of Call]])<=6, YEAR(calls[[#This Row],[Date of Call]]), YEAR(calls[[#This Row],[Date of Call]])+1) -> 2023 | J29: =TEXT(calls[[#This Row],[Date of Call]],"DDDD") -> Monday | K29: {=_xlfn.IFS(calls[[#This Row],[Duration]]<=10,"Under 10 mins", calls[[#This Row],[Duration]]<=30, "10 to 30 mins", calls[[#This Row],[Duration]]<=60, "30 to 60 mins", calls[[#This Row],[Duration]]<=120, "1 to 2 hours", TRUE, "More than 2 hours")} -> 10 to 30 mins | L29: =ROUND(calls[[#This Row],[Satisfaction Rating]],0) -> 4
B30: Call_7297 | C30: C0002 | D30: 73 | E30: R05 | F30: 44935 | G30: 80 | H30: 4.2 | I30: =IF(MONTH(calls[[#This Row],[Date of Call]])<=6, YEAR(calls[[#This Row],[Date of Call]]), YEAR(calls[[#This Row],[Date of Call]])+1) -> 2023 | J30: =TEXT(calls[[#This Row],[Date of Call]],"DDDD") -> Monday | K30: {=_xlfn.IFS(calls[[#This Row],[Duration]]<=10,"Under 10 mins", calls[[#This Row],[Duration]]<=30, "10 to 30 mins", calls[[#This Row],[Duration]]<=60, "30 to 60 mins", calls[[#This Row],[Duration]]<=120, "1 to 2 hours", TRUE, "More than 2 hours")} -> 1 to 2 hours | L30: =ROUND(calls[[#This Row],[Satisfaction Rating]],0) -> 4
... B1003: Call_8270 | C1003: C0009 | D1003: 114 | E1003: R01 | F1003: 45291 | G1003: 40 | H1003: 3.9 | I1003: =IF(MONTH(calls[[#This Row],[Date of Call]])<=6, YEAR(calls[[#This Row],[Date of Call]]), YEAR(calls[[#This Row],[Date of Call]])+1) -> 2024 | J1003: =TEXT(calls[[#This Row],[Date of Call]],"DDDD") -> Sunday | K1003: {=_xlfn.IFS(calls[[#This Row],[Duration]]<=10,"Under 10 mins", calls[[#This Row],[Duration]]<=30, "10 to 30 mins", calls[[#This Row],[Duration]]<=60, "30 to 60 mins", calls[[#This Row],[Duration]]<=120, "1 to 2 hours", TRUE, "More than 2 hours")} -> 1 to 2 hours | L1003: =ROUND(calls[[#This Row],[Satisfaction Rating]],0) -> 4

Sheet Assets
E2: Rep ID | F2: Rep Image | G2: helper column
E3: R01 | G3: ="Assets!" & CELL("address", F3) -> Assets!$F$3
E4: R02 | G4: ="Assets!" & CELL("address", F4) -> Assets!$F$4
E5: R03 | G5: ="Assets!" & CELL("address", F5) -> Assets!$F$5
E6: R04 | G6: ="Assets!" & CELL("address", F6) -> Assets!$F$6
E7: R05 | G7: ="Assets!" & CELL("address", F7) -> Assets!$F$7

Sheet Customer Centre Report
B1: CALL CENTRE REPORT-2025
Q21: =Pivots!F59 -> R01 | R21: =Pivots!G59 -> R02 | S21: =Pivots!H59 -> R03 | T21: =Pivots!I59 -> R04 | U21: =Pivots!J59 -> R05 | V21: TOTAL
P22: =Pivots!E60 -> Cincinnati
P23: =Pivots!E61 -> C0003 | Q23: =Pivots!F61 -> 891 | R23: =Pivots!G61 -> 1332 | S23: =Pivots!H61 -> 1282 | T23: =Pivots!I61 -> 739 | U23: =Pivots!J61 -> 560 | V23: =Pivots!K61 -> 4804
P24: =Pivots!E62 -> C0004 | Q24: =Pivots!F62 -> 1991 | R24: =Pivots!G62 -> 1886 | S24: =Pivots!H62 -> 1206 | T24: =Pivots!I62 -> 884 | U24: =Pivots!J62 -> 1722 | V24: =Pivots!K62 -> 7689
P25: =Pivots!E63 -> C0011 | Q25: =Pivots!F63 -> 1163 | R25: =Pivots!G63 -> 1180 | S25: =Pivots!H63 -> 1616 | T25: =Pivots!I63 -> 1043 | U25: =Pivots!J63 -> 1747 | V25: =Pivots!K63 -> 6749
P26: =Pivots!E64 -> C0012 | Q26: =Pivots!F64 -> 1438 | R26: =Pivots!G64 -> 1616 | S26: =Pivots!H64 -> 866 | T26: =Pivots!I64 -> 829 | U26: =Pivots!J64 -> 2070 | V26: =Pivots!K64 -> 6819
P27: =Pivots!E65 -> Cleveland
P28: =Pivots!E66 -> C0002 | Q28: =Pivots!F66 -> 1233 | R28: =Pivots!G66 -> 223 | S28: =Pivots!H66 -> 1680 | T28: =Pivots!I66 -> 990 | U28: =Pivots!J66 -> 1508 | V28: =Pivots!K66 -> 5634
P29: =Pivots!E67 -> C0007 | Q29: =Pivots!F67 -> 1598 | R29: =Pivots!G67 -> 1907 | S29: =Pivots!H67 -> 869 | T29: =Pivots!I67 -> 1426 | U29: =Pivots!J67 -> 1416 | V29: =Pivots!K67 -> 7216
P30: =Pivots!E68 -> C0008 | Q30: =Pivots!F68 -> 900 | R30: =Pivots!G68 -> 1016 | S30: =Pivots!H68 -> 960 | T30: =Pivots!I68 -> 940 | U30: =Pivots!J68 -> 1193 | V30: =Pivots!K68 -> 5009
P31: =Pivots!E69 -> C0010 | Q31: =Pivots!F69 -> 900 | R31: =Pivots!G69 -> 1470 | S31: =Pivots!H69 -> 1617 | T31: =Pivots!I69 -> 1314 | U31: =Pivots!J69 -> 941 | V31: =Pivots!K69 -> 6242
P32: =Pivots!E70 -> C0013 | Q32: =Pivots!F70 -> 1255 | R32: =Pivots!G70 -> 516 | S32: =Pivots!H70 -> 1874 | T32: =Pivots!I70 -> 1863 | U32: =Pivots!J70 -> 1722 | V32: =Pivots!K70 -> 7230
P33: =Pivots!E71 -> C0015 | Q33: =Pivots!F71 -> 1138 | R33: =Pivots!G71 -> 1898 | S33: =Pivots!H71 -> 1482 | T33: =Pivots!I71 -> 846 | U33: =Pivots!J71 -> 1154 | V33: =Pivots!K71 -> 6518
P34: =Pivots!E72 -> Columbus
P35: =Pivots!E73 -> C0001 | Q35: =Pivots!F73 -> 1655 | R35: =Pivots!G73 -> 805 | S35: =Pivots!H73 -> 2263 | T35: =Pivots!I73 -> 987 | U35: =Pivots!J73 -> 1075 | V35: =Pivots!K73 -> 6785
P36: =Pivots!E74 -> C0005 | Q36: =Pivots!F74 -> 1104 | R36: =Pivots!G74 -> 2280 | S36: =Pivots!H74 -> 1445 | T36: =Pivots!I74 -> 1722 | U36: =Pivots!J74 -> 1196 | V36: =Pivots!K74 -> 7747
M37: =Pivots!$N$61 -> % of calls: 19% | P37: =Pivots!E75 -> C0006 | Q37: =Pivots!F75 -> 372 | R37: =Pivots!G75 -> 1818 | S37: =Pivots!H75 -> 1346 | T37: =Pivots!I75 -> 1156 | U37: =Pivots!J75 -> 1484 | V37: =Pivots!K75 -> 6176
M38: =Pivots!$N$62 -> Call Rank: 5 | P38: =Pivots!E76 -> C0009 | Q38: =Pivots!F76 -> 1415 | R38: =Pivots!G76 -> 1271 | S38: =Pivots!H76 -> 1214 | T38: =Pivots!I76 -> 1135 | U38: =Pivots!J76 -> 1566 | V38: =Pivots!K76 -> 6601
M39: =Pivots!$N$63 -> Amount Rank :5 | P39: =Pivots!E77 -> C0014 | Q39: =Pivots!F77 -> 1362 | R39: =Pivots!G77 -> 1363 | S39: =Pivots!H77 -> 1152 | T39: =Pivots!I77 -> 777 | U39: =Pivots!J77 -> 750 | V39: =Pivots!K77 -> 5404
